Workbook
Name Type: '[1]Risk Assessment & Control'!#REF!

Sheet DCF Model with Valuation
B1: DCF MODEL WITH COMPANY VALUATION
B2: COMPANY NAME | C2: START YEAR | D2: YEARS ENDING | E2: STOCK TICKER SYMBOL | F2: CURRENT PRICE
B3: {=_FV(E3,"Name")} -> EVOLV TECHNOLOGIES HOLDINGS, INC. | C3: 2026 | D3: DEC 31st | E3: #VALUE! | F3: {=_FV(E3,"Price")} -> 7.11
B4: Complete non-shaded cells only.
B5: FORECASTING VARIABLES
B6: YEAR | D6: =C3 -> 2026 | E6: =D6+1 -> 2027 | F6: =E6+1 -> 2028 | G6: =F6+1 -> 2029 | H6: =G6+1 -> 2030 | I6: =H6+1 -> 2031 | J6: =I6+1 -> 2032 | K6: =J6+1 -> 2033 | L6: =K6+1 -> 2034 | M6: =L6+1 -> 2035
B7: REVENUE GROWTH FACTOR | D7: 0.4 | E7: 0.3 | F7: 0.2 | G7: 0.15 | H7: 0.1 | I7: 0.08 | J7: 0.05 | K7: 0.05 | L7: 0.03 | M7: 0.03
B8: EXPECTED GROSS PROFIT MARGIN | D8: 0.53 | E8: 0.55 | F8: 0.56 | G8: 0.57 | H8: 0.58 | I8: 0.59 | J8: 0.6 | K8: 0.6 | L8: 0.6 | M8: 0.6
B9: S, G, & A EXPENSE % OF REVENUE | D9: 0.6 | E9: 0.63 | F9: 0.47 | G9: 0.42 | H9: 0.38 | I9: 0.35 | J9: 0.32 | K9: 0.3 | L9: 0.28 | M9: 0.27
B10: DEPRECIATION & AMORTIZATION % OF REVENUE | D10: 0.16 | E10: 0.14 | F10: 0.13 | G10: 0.12 | H10: 0.11 | I10: 0.1 | J10: 0.1 | K10: 0.09 | L10: 0.09 | M10: 0.09
B11: CAPITAL EXPENDITURE GROWTH FACTOR | D11: 0.1 | E11: 0.1 | F11: 0.08 | G11: 0.06 | H11: 0.05 | I11: 0.04 | J11: 0.03 | K11: 0.03 | L11: 0.03 | M11: 0.03
B12: NET WORKING CAPITAL TO SALES RATIO | D12: 0.05 | E12: 0.08 | F12: 0.1 | G12: 0.12 | H12: 0.15 | I12: 0.15 | J12: 0.15 | K12: 0.15 | L12: 0.15 | M12: 0.15
B14: INCOME TAX RATE | C14: 0.21
B15: ASSUMED LONG-TERM SUSTAINABLE GROWTH RATE | C15: 0.02 | D15: PER YEAR AFTER | E15: =M6 -> 2035
B16: DISCOUNT RATE | C16: =WACC!F9 -> 0.14070057
B18: VALUATION MODEL OUTPUTS
B19: YEAR | D19: =D6 -> 2026 | E19: =E6 -> 2027 | F19: =F6 -> 2028 | G19: =G6 -> 2029 | H19: =H6 -> 2030 | I19: =I6 -> 2031 | J19: =J6 -> 2032 | K19: =K6 -> 2033 | ... M19: =M6 -> 2035
B20: GROSS PROFIT MARGIN | D20: =IFERROR('DCF Model with Valuation'!D35/'DCF Model with Valuation'!D32,"") -> 0.5300024 | E20: =IFERROR('DCF Model with Valuation'!E35/'DCF Model with Valuation'!E32,"") -> 0.55000073 | F20: =IFERROR('DCF Model with Valuation'!F35/'DCF Model with Valuation'!F32,"") -> 0.55999959 | G20: =IFERROR('DCF Model with Valuation'!G35/'DCF Model with Valuation'!G32,"") -> 0.56999904 | H20: =IFERROR('DCF Model with Valuation'!H35/'DCF Model with Valuation'!H32,"") -> 0.58000052 | I20: =IFERROR('DCF Model with Valuation'!I35/'DCF Model with Valuation'!I32,"") -> 0.58999977 | J20: =IFERROR('DCF Model with Valuation'!J35/'DCF Model with Valuation'!J32,"") -> 0.60000084 | K20: =IFERROR('DCF Model with Valuation'!K35/'DCF Model with Valuation'!K32,"") -> 0.59999939 | ... M20: =IFERROR('DCF Model with Valuation'!M35/'DCF Model with Valuation'!M32,"") -> 0.59999964
B21: NET OPERATING PROFIT MARGIN | D21: =IFERROR('DCF Model with Valuation'!D46/'DCF Model with Valuation'!D32,"") -> -0.22999799 | E21: =IFERROR('DCF Model with Valuation'!E46/'DCF Model with Valuation'!E32,"") -> -0.22000203 | F21: =IFERROR('DCF Model with Valuation'!F46/'DCF Model with Valuation'!F32,"") -> -0.040000688 | G21: =IFERROR('DCF Model with Valuation'!G46/'DCF Model with Valuation'!G32,"") -> 0.029998221 | H21: =IFERROR('DCF Model with Valuation'!H46/'DCF Model with Valuation'!H32,"") -> 0.090001124 | I21: =IFERROR('DCF Model with Valuation'!I46/'DCF Model with Valuation'!I32,"") -> 0.13999941 | J21: =IFERROR('DCF Model with Valuation'!J46/'DCF Model with Valuation'!J32,"") -> 0.1800002 | K21: =IFERROR('DCF Model with Valuation'!K46/'DCF Model with Valuation'!K32,"") -> 0.20999936 | ... M21: =IFERROR('DCF Model with Valuation'!M46/'DCF Model with Valuation'!M32,"") -> 0.21517768
B22: FREE CASH FLOW ($ MIL) | D22: ='DCF Model with Valuation'!D51/1000000 -> -0.0154862 | E22: ='DCF Model with Valuation'!E51/1000000 -> -0.020858422 | F22: ='DCF Model with Valuation'!F51/1000000 -> 0.029111178 | G22: ='DCF Model with Valuation'!G51/1000000 -> 0.055532834 | H22: ='DCF Model with Valuation'!H51/1000000 -> 0.080687792 | I22: ='DCF Model with Valuation'!I51/1000000 -> 0.10367403 | J22: ='DCF Model with Valuation'!J51/1000000 -> 0.12544197 | K22: ='DCF Model with Valuation'!K51/1000000 -> 0.14142854 | ... M22: ='DCF Model with Valuation'!M51/1000000 -> 0.151266
B23: TERMINAL VALUE ($ MIL) | M23: ='DCF Model with Valuation'!M53/1000000 -> 1.278298
B25: PRESENT VALUE OF COMPANY OPERATIONS ($ MIL) | D25: ='DCF Model with Valuation'!C57/1000000 -> 0.641302
B27: MARKET VALUE OF COMPANY ASSETS ($ MIL) | D27: ='DCF Model with Valuation'!C63/1000000 -> 0.698224
C29: ACTUAL | D29: FORECAST ––>
C30: =D6-1 -> 2025 | D30: =C30+1 -> 2026 | E30: =D30+1 -> 2027 | F30: =E30+1 -> 2028 | G30: =F30+1 -> 2029 | H30: =G30+1 -> 2030 | I30: =H30+1 -> 2031 | J30: =I30+1 -> 2032 | K30: =J30+1 -> 2033 | ... M30: =L30+1 -> 2035
B32: TOTAL REVENUE | C32: 145905 | D32: =C32*(1+'DCF Model with Valuation'!D7) -> 204267 | E32: =D32*(1+'DCF Model with Valuation'!E7) -> 265547.1 | F32: =E32*(1+'DCF Model with Valuation'!F7) -> 318656.52 | G32: =F32*(1+'DCF Model with Valuation'!G7) -> 366455 | H32: =G32*(1+'DCF Model with Valuation'!H7) -> 403100.5 | I32: =H32*(1+'DCF Model with Valuation'!I7) -> 435348.54 | J32: =I32*(1+'DCF Model with Valuation'!J7) -> 457115.96 | K32: =J32*(1+'DCF Model with Valuation'!K7) -> 479971.76 | ... M32: =L32*(1+'DCF Model with Valuation'!M7) -> 509202.04
B34: COST OF GOODS SOLD | C34: 70603 | D34: =ROUND((D32*(1-'DCF Model with Valuation'!D8)),0) -> 96005 | E34: =ROUND((E32*(1-'DCF Model with Valuation'!E8)),0) -> 119496 | F34: =ROUND((F32*(1-'DCF Model with Valuation'!F8)),0) -> 140209 | G34: =ROUND((G32*(1-'DCF Model with Valuation'!G8)),0) -> 157576 | H34: =ROUND((H32*(1-'DCF Model with Valuation'!H8)),0) -> 169302 | I34: =ROUND((I32*(1-'DCF Model with Valuation'!I8)),0) -> 178493 | J34: =ROUND((J32*(1-'DCF Model with Valuation'!J8)),0) -> 182846 | K34: =ROUND((K32*(1-'DCF Model with Valuation'!K8)),0) -> 191989 | ... M34: =ROUND((M32*(1-'DCF Model with Valuation'!M8)),0) -> 203681
B35: GROSS PROFIT | C35: 75302 | D35: =D32-D34 -> 108262 | E35: =E32-E34 -> 146051.1 | F35: =F32-F34 -> 178447.52 | G35: =G32-G34 -> 208879 | H35: =H32-H34 -> 233798.5 | I35: =I32-I34 -> 256855.54 | J35: =J32-J34 -> 274269.96 | K35: =K32-K34 -> 287982.76 | ... M35: =M32-M34 -> 305521.04
B37: SELLING, GENERAL AND ADMINISTRATIVE EXPENSES | C37: =185897+160635+59796-6491 -> 399837 | D37: =ROUND((D32*'DCF Model with Valuation'!D9),0) -> 122560 | E37: =ROUND((E32*'DCF Model with Valuation'!E9),0) -> 167295 | F37: =ROUND((F32*'DCF Model with Valuation'!F9),0) -> 149769 | G37: =ROUND((G32*'DCF Model with Valuation'!G9),0) -> 153911 | H37: =ROUND((H32*'DCF Model with Valuation'!H9),0) -> 153178 | I37: =ROUND((I32*'DCF Model with Valuation'!I9),0) -> 152372 | J37: =ROUND((J32*'DCF Model with Valuation'!J9),0) -> 146277 | K37: =ROUND((K32*'DCF Model with Valuation'!K9),0) -> 143992 | ... M37: =ROUND((M32*'DCF Model with Valuation'!M9),0) -> 137485
B38: EARNINGS BEFORE INTEREST, TAXES, DEPR. & AMORT. (EBITDA) | C38: =C35-C37 -> -324535 | D38: =D35-D37 -> -14298 | E38: =E35-E37 -> -21243.9 | F38: =F35-F37 -> 28678.52 | G38: =G35-G37 -> 54967.998 | H38: =H35-H37 -> 80620.498 | I38: =I35-I37 -> 104483.54 | J38: =J35-J37 -> 127992.96 | ... M38: =M35-M37 -> 168036.04
B40: DEPRECIATION AND AMORTIZATION | C40: 24340 | D40: =ROUND((D32*'DCF Model with Valuation'!D10),0) -> 32683 | E40: =ROUND((E32*'DCF Model with Valuation'!E10),0) -> 37177 | F40: =ROUND((F32*'DCF Model with Valuation'!F10),0) -> 41425 | G40: =ROUND((G32*'DCF Model with Valuation'!G10),0) -> 43975 | H40: =ROUND((H32*'DCF Model with Valuation'!H10),0) -> 44341 | I40: =ROUND((I32*'DCF Model with Valuation'!I10),0) -> 43535 | J40: =ROUND((J32*'DCF Model with Valuation'!J10),0) -> 45712 | K40: =ROUND((K32*'DCF Model with Valuation'!K10),0) -> 43197 | ... M40: =ROUND((M32*'DCF Model with Valuation'!M10),0) -> 45828
B41: EARNINGS BEFORE INTEREST AND TAXES (EBIT) | C41: =C38-C40 -> -348875 | D41: =D38-D40 -> -46981 | E41: =E38-E40 -> -58420.9 | F41: =F38-F40 -> -12746.48 | G41: =G38-G40 -> 10992.998 | H41: =H38-H40 -> 36279.498 | I41: =I38-I40 -> 60948.538 | J41: =J38-J40 -> 82280.965 | ... M41: =M38-M40 -> 122208.04
B42: AVAILABLE TAX-LOSS CARRYFORWARDS | C42: 0 | D42: =IF(C42+C41<0,C42+C41,0) -> -348875 | E42: =IF(D42+D41<0,D42+D41,0) -> -395856 | F42: =IF(E42+E41<0,E42+E41,0) -> -454276.9 | G42: =IF(F42+F41<0,F42+F41,0) -> -467023.38 | H42: =IF(G42+G41<0,G42+G41,0) -> -456030.38 | I42: =IF(H42+H41<0,H42+H41,0) -> -419750.88 | J42: =IF(I42+I41<0,I42+I41,0) -> -358802.35 | K42: =IF(J42+J41<0,J42+J41,0) -> -276521.38 | ... M42: =IF(L42+L41<0,L42+L41,0) -> -62021.704
B43: NET TAXABLE EARNINGS | C43: =IF(SUM(C41:C42)<0,0,SUM(C41:C42)) -> 0 | D43: =IF(SUM(D41:D42)<0,0,SUM(D41:D42)) -> 0 | E43: =IF(SUM(E41:E42)<0,0,SUM(E41:E42)) -> 0 | F43: =IF(SUM(F41:F42)<0,0,SUM(F41:F42)) -> 0 | G43: =IF(SUM(G41:G42)<0,0,SUM(G41:G42)) -> 0 | H43: =IF(SUM(H41:H42)<0,0,SUM(H41:H42)) -> 0 | I43: =IF(SUM(I41:I42)<0,0,SUM(I41:I42)) -> 0 | J43: =IF(SUM(J41:J42)<0,0,SUM(J41:J42)) -> 0 | ... M43: =IF(SUM(M41:M42)<0,0,SUM(M41:M42)) -> 60186.339
B45: FEDERAL AND STATE INCOME TAXES | C45: 299222 | D45: =D43*'DCF Model with Valuation'!$C$14 -> 0 | E45: =E43*'DCF Model with Valuation'!$C$14 -> 0 | F45: =F43*'DCF Model with Valuation'!$C$14 -> 0 | G45: =G43*'DCF Model with Valuation'!$C$14 -> 0 | H45: =H43*'DCF Model with Valuation'!$C$14 -> 0 | I45: =I43*'DCF Model with Valuation'!$C$14 -> 0 | J45: =J43*'DCF Model with Valuation'!$C$14 -> 0 | K45: =K43*'DCF Model with Valuation'!$C$14 -> 0 | ... M45: =M43*'DCF Model with Valuation'!$C$14 -> 12639.131
B46: NET OPERATING PROFIT AFTER-TAX (NOPAT) | C46: =C41-C45 -> -648097 | D46: =D41-D45 -> -46981 | E46: =E41-E45 -> -58420.9 | F46: =F41-F45 -> -12746.48 | G46: =G41-G45 -> 10992.998 | H46: =H41-H45 -> 36279.498 | I46: =I41-I45 -> 60948.538 | J46: =J41-J45 -> 82280.965 | ... M46: =M41-M45 -> 109568.91
B48: ADD BACK DEPRECIATION AND AMORTIZATION | C48: =C40 -> 24340 | D48: =D40 -> 32683 | E48: =E40 -> 37177 | F48: =F40 -> 41425 | G48: =G40 -> 43975 | H48: =H40 -> 44341 | I48: =I40 -> 43535 | J48: =J40 -> 45712 | ... M48: =M40 -> 45828
B49: SUBTRACT CAPITAL EXPENDITURES | C49: -3733 | D49: =C49*(1+'DCF Model with Valuation'!D11) -> -4106.3 | E49: =D49*(1+'DCF Model with Valuation'!E11) -> -4516.93 | F49: =E49*(1+'DCF Model with Valuation'!F11) -> -4878.2844 | G49: =F49*(1+'DCF Model with Valuation'!G11) -> -5170.9815 | H49: =G49*(1+'DCF Model with Valuation'!H11) -> -5429.5305 | I49: =H49*(1+'DCF Model with Valuation'!I11) -> -5646.7118 | J49: =I49*(1+'DCF Model with Valuation'!J11) -> -5816.1131 | K49: =J49*(1+'DCF Model with Valuation'!K11) -> -5990.5965 | ... M49: =L49*(1+'DCF Model with Valuation'!M11) -> -6355.4238
B50: SUBTRACT NEW NET WORKING CAPITAL | D50: =(D32-C32)*'DCF Model with Valuation'!D12 -> 2918.1 | E50: =(E32-D32)*'DCF Model with Valuation'!E12 -> 4902.408 | F50: =(F32-E32)*'DCF Model with Valuation'!F12 -> 5310.942 | G50: =(G32-F32)*'DCF Model with Valuation'!G12 -> 5735.8174 | H50: =(H32-G32)*'DCF Model with Valuation'!H12 -> 5496.825 | I50: =(I32-H32)*'DCF Model with Valuation'!I12 -> 4837.206 | J50: =(J32-I32)*'DCF Model with Valuation'!J12 -> 3265.114 | K50: =(K32-J32)*'DCF Model with Valuation'!K12 -> 3428.3697 | ... M50: =(M32-L32)*'DCF Model with Valuation'!M12 -> 2224.6691
B51: FREE CASH FLOW | C51: =SUM(C46:C50) -> -627490 | D51: =SUM(D46:D50) -> -15486.2 | E51: =SUM(E46:E50) -> -20858.422 | F51: =SUM(F46:F50) -> 29111.178 | G51: =SUM(G46:G50) -> 55532.834 | H51: =SUM(H46:H50) -> 80687.792 | I51: =SUM(I46:I50) -> 103674.03 | J51: =SUM(J46:J50) -> 125441.97 | ... L51: =SUM(L46:L50) -> 154188.47 | M51: =ROUND((SUM(M46:M50)),0) -> 151266
...

Sheet WACC
B1: WEIGHTED AVERAGE COST OF CAPITAL
B3: COST OF EQUITY (CAPM): | E3: CAPITAL STRUCTURE:
B4: MARKET RISK PREMIUM | C4: =0.1-C6 -> 0.0558 | E4: TOTAL EQUITY (MARKET CAP $) | F4: 1262000 | G4: 1.261B | H4: ='DCF Model with Valuation'!C64*'DCF Model with Valuation'!C67 -> 1197459.1
B5: BETA | C5: 1.78 | E5: MARKET VALUE OF DEBT ($) | F5: 28528
B6: RISK FREE RATE | C6: 0.0442 | E6: TOTAL CAPITALIZATION | F6: =SUM(F4:F5) -> 1290528
B7: COST OF EQUITY | C7: =C6+(C5*C4) -> 0.143524 | E7: WEIGHT OF EQUITY (%) | F7: =F4/F6 -> 0.97789432
E8: WEIGHT OF DEBT (%) | F8: =F5/F6 -> 0.022105681
B9: COST OF EQUITY (DIVIDEND GROWTH): | E9: WACC: | F9: =(F7*C15)+(F8*C21) -> 0.14070057
B10: EXPECTED DIVIDEND (D1)
B11: CURRENT PRICE (P0)
B12: EXPECTED GROWTH RATE (g)
B13: COST OF EQUITY
B15: AVERAGE COST OF EQUITY | C15: =C7 -> 0.143524
B18: COST OF DEBT:
B19: BEFORE-TAX COST OF DEBT | C19: 0.02
B20: TAX RATE | C20: 0.21
B21: AFTER-TAX COST OF DEBT | C21: =C19*(1-C20) -> 0.0158

Sheet Sensitivity Analysis(Bull)
B1: DCF MODEL WITH COMPANY VALUATION
B2: COMPANY NAME | C2: START YEAR | D2: YEARS ENDING | E2: STOCK TICKER SYMBOL | F2: CURRENT PRICE
B3: {=_FV(E3,"Name")} -> EVOLV TECHNOLOGIES HOLDINGS, INC. | C3: 2026 | D3: DEC 31st | E3: #VALUE! | F3: {=_FV(E3,"Price")} -> 6.24
B4: Complete non-shaded cells only.
B5: FORECASTING VARIABLES
B6: YEAR | D6: =C3 -> 2026 | E6: =D6+1 -> 2027 | F6: =E6+1 -> 2028 | G6: =F6+1 -> 2029 | H6: =G6+1 -> 2030 | I6: =H6+1 -> 2031 | J6: =I6+1 -> 2032 | K6: =J6+1 -> 2033 | L6: =K6+1 -> 2034 | M6: =L6+1 -> 2035
B7: REVENUE GROWTH FACTOR | D7: 0.4 | E7: 0.34 | F7: 0.29 | G7: 0.23 | H7: 0.17 | I7: 0.14 | J7: 0.11 | K7: 0.09 | L7: 0.06 | M7: 0.03
B8: EXPECTED GROSS PROFIT MARGIN | D8: 0.55 | E8: 0.57 | F8: 0.58 | G8: 0.59 | H8: 0.6 | I8: 0.61 | J8: 0.62 | K8: 0.62 | L8: 0.62 | M8: 0.62
B9: S, G, & A EXPENSE % OF REVENUE | D9: 0.57 | E9: 0.5 | F9: 0.44 | G9: 0.39 | H9: 0.35 | I9: 0.32 | J9: 0.29 | K9: 0.27 | L9: 0.25 | M9: 0.24
B10: DEPRECIATION & AMORTIZATION % OF REVENUE | D10: 0.15 | E10: 0.13 | F10: 0.12 | G10: 0.11 | H10: 0.1 | I10: 0.09 | J10: 0.09 | K10: 0.08 | L10: 0.08 | M10: 0.07
B11: CAPITAL EXPENDITURE GROWTH FACTOR | D11: 0.09 | E11: 0.09 | F11: 0.07 | G11: 0.05 | H11: 0.04 | I11: 0.03 | J11: 0.03 | K11: 0.03 | L11: 0.03 | M11: 0.03
B12: NET WORKING CAPITAL TO SALES RATIO | D12: 0.03 | E12: 0.06 | F12: 0.08 | G12: 0.1 | H12: 0.13 | I12: 0.13 | J12: 0.13 | K12: 0.13 | L12: 0.13 | M12: 0.13
B14: INCOME TAX RATE | C14: 0.21
B15: ASSUMED LONG-TERM SUSTAINABLE GROWTH RATE | C15: 0.02 | D15: PER YEAR AFTER | E15: =M6 -> 2035
B16: DISCOUNT RATE | C16: =WACC!F9 -> 0.14070057
B18: VALUATION MODEL OUTPUTS
B19: YEAR | D19: =D6 -> 2026 | E19: =E6 -> 2027 | F19: =F6 -> 2028 | G19: =G6 -> 2029 | H19: =H6 -> 2030 | I19: =I6 -> 2031 | J19: =J6 -> 2032 | K19: =K6 -> 2033 | ... M19: =M6 -> 2035
B20: GROSS PROFIT MARGIN | D20: =IFERROR('Sensitivity Analysis(Bull)'!D35/'Sensitivity Analysis(Bull)'!D32,"") -> 0.55000073 | E20: =IFERROR('Sensitivity Analysis(Bull)'!E35/'Sensitivity Analysis(Bull)'!E32,"") -> 0.5699987 | F20: =IFERROR('Sensitivity Analysis(Bull)'!F35/'Sensitivity Analysis(Bull)'!F32,"") -> 0.58000083 | G20: =IFERROR('Sensitivity Analysis(Bull)'!G35/'Sensitivity Analysis(Bull)'!G32,"") -> 0.59000065 | H20: =IFERROR('Sensitivity Analysis(Bull)'!H35/'Sensitivity Analysis(Bull)'!H32,"") -> 0.60000028 | I20: =IFERROR('Sensitivity Analysis(Bull)'!I35/'Sensitivity Analysis(Bull)'!I32,"") -> 0.61000035 | J20: =IFERROR('Sensitivity Analysis(Bull)'!J35/'Sensitivity Analysis(Bull)'!J32,"") -> 0.62000048 | K20: =IFERROR('Sensitivity Analysis(Bull)'!K35/'Sensitivity Analysis(Bull)'!K32,"") -> 0.61999991 | ... M20: =IFERROR('Sensitivity Analysis(Bull)'!M35/'Sensitivity Analysis(Bull)'!M32,"") -> 0.62000015
B21: NET OPERATING PROFIT MARGIN | D21: =IFERROR('Sensitivity Analysis(Bull)'!D46/'Sensitivity Analysis(Bull)'!D32,"") -> -0.16999809 | E21: =IFERROR('Sensitivity Analysis(Bull)'!E46/'Sensitivity Analysis(Bull)'!E32,"") -> -0.06000056 | F21: =IFERROR('Sensitivity Analysis(Bull)'!F46/'Sensitivity Analysis(Bull)'!F32,"") -> 0.020000049 | G21: =IFERROR('Sensitivity Analysis(Bull)'!G46/'Sensitivity Analysis(Bull)'!G32,"") -> 0.090000648 | H21: =IFERROR('Sensitivity Analysis(Bull)'!H46/'Sensitivity Analysis(Bull)'!H32,"") -> 0.15000061 | I21: =IFERROR('Sensitivity Analysis(Bull)'!I46/'Sensitivity Analysis(Bull)'!I32,"") -> 0.20000002 | J21: =IFERROR('Sensitivity Analysis(Bull)'!J46/'Sensitivity Analysis(Bull)'!J32,"") -> 0.24000096 | K21: =IFERROR('Sensitivity Analysis(Bull)'!K46/'Sensitivity Analysis(Bull)'!K32,"") -> 0.21553946 | ... M21: =IFERROR('Sensitivity Analysis(Bull)'!M46/'Sensitivity Analysis(Bull)'!M32,"") -> 0.24489946
B22: FREE CASH FLOW ($ MIL) | D22: ='Sensitivity Analysis(Bull)'!D51/1000000 -> -0.00640311 | E22: ='Sensitivity Analysis(Bull)'!E51/1000000 -> 0.01889165 | F22: ='Sensitivity Analysis(Bull)'!F51/1000000 -> 0.051038549 | G22: ='Sensitivity Analysis(Bull)'!G51/1000000 -> 0.090000286 | H22: ='Sensitivity Analysis(Bull)'!H51/1000000 -> 0.13145133 | I22: ='Sensitivity Analysis(Bull)'!I51/1000000 -> 0.17190146 | J22: ='Sensitivity Analysis(Bull)'!J51/1000000 -> 0.21497668 | K22: ='Sensitivity Analysis(Bull)'!K51/1000000 -> 0.20899567 | ... M22: ='Sensitivity Analysis(Bull)'!M51/1000000 -> 0.237854
B23: TERMINAL VALUE ($ MIL) | M23: ='Sensitivity Analysis(Bull)'!M53/1000000 -> 2.010024
B25: PRESENT VALUE OF COMPANY OPERATIONS ($ MIL) | D25: ='Sensitivity Analysis(Bull)'!C57/1000000 -> 1.07374
B27: MARKET VALUE OF COMPANY ASSETS ($ MIL) | D27: ='Sensitivity Analysis(Bull)'!C63/1000000 -> 1.130662
C29: ACTUAL | D29: FORECAST ––>
C30: =D6-1 -> 2025 | D30: =C30+1 -> 2026 | E30: =D30+1 -> 2027 | F30: =E30+1 -> 2028 | G30: =F30+1 -> 2029 | H30: =G30+1 -> 2030 | I30: =H30+1 -> 2031 | J30: =I30+1 -> 2032 | K30: =J30+1 -> 2033 | ... M30: =L30+1 -> 2035
B32: TOTAL REVENUE | C32: 145905 | D32: =C32*(1+'Sensitivity Analysis(Bull)'!D7) -> 204267 | E32: =D32*(1+'Sensitivity Analysis(Bull)'!E7) -> 273717.78 | F32: =E32*(1+'Sensitivity Analysis(Bull)'!F7) -> 353095.94 | G32: =F32*(1+'Sensitivity Analysis(Bull)'!G7) -> 434308 | H32: =G32*(1+'Sensitivity Analysis(Bull)'!H7) -> 508140.36 | I32: =H32*(1+'Sensitivity Analysis(Bull)'!I7) -> 579280.01 | J32: =I32*(1+'Sensitivity Analysis(Bull)'!J7) -> 643000.81 | K32: =J32*(1+'Sensitivity Analysis(Bull)'!K7) -> 700870.89 | ... M32: =L32*(1+'Sensitivity Analysis(Bull)'!M7) -> 765210.83
B34: COST OF GOODS SOLD | C34: 70603 | D34: =ROUND((D32*(1-'Sensitivity Analysis(Bull)'!D8)),0) -> 91920 | E34: =ROUND((E32*(1-'Sensitivity Analysis(Bull)'!E8)),0) -> 117699 | F34: =ROUND((F32*(1-'Sensitivity Analysis(Bull)'!F8)),0) -> 148300 | G34: =ROUND((G32*(1-'Sensitivity Analysis(Bull)'!G8)),0) -> 178066 | H34: =ROUND((H32*(1-'Sensitivity Analysis(Bull)'!H8)),0) -> 203256 | I34: =ROUND((I32*(1-'Sensitivity Analysis(Bull)'!I8)),0) -> 225919 | J34: =ROUND((J32*(1-'Sensitivity Analysis(Bull)'!J8)),0) -> 244340 | K34: =ROUND((K32*(1-'Sensitivity Analysis(Bull)'!K8)),0) -> 266331 | ... M34: =ROUND((M32*(1-'Sensitivity Analysis(Bull)'!M8)),0) -> 290780
B35: GROSS PROFIT | C35: 75302 | D35: =D32-D34 -> 112347 | E35: =E32-E34 -> 156018.78 | F35: =F32-F34 -> 204795.94 | G35: =G32-G34 -> 256242 | H35: =H32-H34 -> 304884.36 | I35: =I32-I34 -> 353361.01 | J35: =J32-J34 -> 398660.81 | K35: =K32-K34 -> 434539.89 | ... M35: =M32-M34 -> 474430.83
B37: SELLING, GENERAL AND ADMINISTRATIVE EXPENSES | C37: =185897+160635+59796-6491 -> 399837 | D37: =ROUND((D32*'Sensitivity Analysis(Bull)'!D9),0) -> 116432 | E37: =ROUND((E32*'Sensitivity Analysis(Bull)'!E9),0) -> 136859 | F37: =ROUND((F32*'Sensitivity Analysis(Bull)'!F9),0) -> 155362 | G37: =ROUND((G32*'Sensitivity Analysis(Bull)'!G9),0) -> 169380 | H37: =ROUND((H32*'Sensitivity Analysis(Bull)'!H9),0) -> 177849 | I37: =ROUND((I32*'Sensitivity Analysis(Bull)'!I9),0) -> 185370 | J37: =ROUND((J32*'Sensitivity Analysis(Bull)'!J9),0) -> 186470 | K37: =ROUND((K32*'Sensitivity Analysis(Bull)'!K9),0) -> 189235 | ... M37: =ROUND((M32*'Sensitivity Analysis(Bull)'!M9),0) -> 183651
B38: EARNINGS BEFORE INTEREST, TAXES, DEPR. & AMORT. (EBITDA) | C38: =C35-C37 -> -324535 | D38: =D35-D37 -> -4085 | E38: =E35-E37 -> 19159.78 | F38: =F35-F37 -> 49433.936 | G38: =G35-G37 -> 86862.002 | H38: =H35-H37 -> 127035.36 | I38: =I35-I37 -> 167991.01 | J38: =J35-J37 -> 212190.81 | ... M38: =M35-M37 -> 290779.83
B40: DEPRECIATION AND AMORTIZATION | C40: 24340 | D40: =ROUND((D32*'Sensitivity Analysis(Bull)'!D10),0) -> 30640 | E40: =ROUND((E32*'Sensitivity Analysis(Bull)'!E10),0) -> 35583 | F40: =ROUND((F32*'Sensitivity Analysis(Bull)'!F10),0) -> 42372 | G40: =ROUND((G32*'Sensitivity Analysis(Bull)'!G10),0) -> 47774 | H40: =ROUND((H32*'Sensitivity Analysis(Bull)'!H10),0) -> 50814 | I40: =ROUND((I32*'Sensitivity Analysis(Bull)'!I10),0) -> 52135 | J40: =ROUND((J32*'Sensitivity Analysis(Bull)'!J10),0) -> 57870 | K40: =ROUND((K32*'Sensitivity Analysis(Bull)'!K10),0) -> 56070 | ... M40: =ROUND((M32*'Sensitivity Analysis(Bull)'!M10),0) -> 53565
B41: EARNINGS BEFORE INTEREST AND TAXES (EBIT) | C41: =C38-C40 -> -348875 | D41: =D38-D40 -> -34725 | E41: =E38-E40 -> -16423.22 | F41: =F38-F40 -> 7061.9362 | G41: =G38-G40 -> 39088.002 | H41: =H38-H40 -> 76221.362 | I41: =I38-I40 -> 115856.01 | J41: =J38-J40 -> 154320.81 | ... M41: =M38-M40 -> 237214.83
B42: AVAILABLE TAX-LOSS CARRYFORWARDS | C42: 0 | D42: =IF(C42+C41<0,C42+C41,0) -> -348875 | E42: =IF(D42+D41<0,D42+D41,0) -> -383600 | F42: =IF(E42+E41<0,E42+E41,0) -> -400023.22 | G42: =IF(F42+F41<0,F42+F41,0) -> -392961.28 | H42: =IF(G42+G41<0,G42+G41,0) -> -353873.28 | I42: =IF(H42+H41<0,H42+H41,0) -> -277651.92 | J42: =IF(I42+I41<0,I42+I41,0) -> -161795.91 | K42: =IF(J42+J41<0,J42+J41,0) -> -7475.0942 | ... M42: =IF(L42+L41<0,L42+L41,0) -> 0
B43: NET TAXABLE EARNINGS | C43: =IF(SUM(C41:C42)<0,0,SUM(C41:C42)) -> 0 | D43: =IF(SUM(D41:D42)<0,0,SUM(D41:D42)) -> 0 | E43: =IF(SUM(E41:E42)<0,0,SUM(E41:E42)) -> 0 | F43: =IF(SUM(F41:F42)<0,0,SUM(F41:F42)) -> 0 | G43: =IF(SUM(G41:G42)<0,0,SUM(G41:G42)) -> 0 | H43: =IF(SUM(H41:H42)<0,0,SUM(H41:H42)) -> 0 | I43: =IF(SUM(I41:I42)<0,0,SUM(I41:I42)) -> 0 | J43: =IF(SUM(J41:J42)<0,0,SUM(J41:J42)) -> 0 | ... M43: =IF(SUM(M41:M42)<0,0,SUM(M41:M42)) -> 237214.83
B45: FEDERAL AND STATE INCOME TAXES | C45: 299222 | D45: =D43*'Sensitivity Analysis(Bull)'!$C$14 -> 0 | E45: =E43*'Sensitivity Analysis(Bull)'!$C$14 -> 0 | F45: =F43*'Sensitivity Analysis(Bull)'!$C$14 -> 0 | G45: =G43*'Sensitivity Analysis(Bull)'!$C$14 -> 0 | H45: =H43*'Sensitivity Analysis(Bull)'!$C$14 -> 0 | I45: =I43*'Sensitivity Analysis(Bull)'!$C$14 -> 0 | J45: =J43*'Sensitivity Analysis(Bull)'!$C$14 -> 0 | K45: =K43*'Sensitivity Analysis(Bull)'!$C$14 -> 38169.556 | ... M45: =M43*'Sensitivity Analysis(Bull)'!$C$14 -> 49815.115
B46: NET OPERATING PROFIT AFTER-TAX (NOPAT) | C46: =C41-C45 -> -648097 | D46: =D41-D45 -> -34725 | E46: =E41-E45 -> -16423.22 | F46: =F41-F45 -> 7061.9362 | G46: =G41-G45 -> 39088.002 | H46: =H41-H45 -> 76221.362 | I46: =I41-I45 -> 115856.01 | J46: =J41-J45 -> 154320.81 | ... M46: =M41-M45 -> 187399.72
B48: ADD BACK DEPRECIATION AND AMORTIZATION | C48: =C40 -> 24340 | D48: =D40 -> 30640 | E48: =E40 -> 35583 | F48: =F40 -> 42372 | G48: =G40 -> 47774 | H48: =H40 -> 50814 | I48: =I40 -> 52135 | J48: =J40 -> 57870 | ... M48: =M40 -> 53565
B49: SUBTRACT CAPITAL EXPENDITURES | C49: -3733 | D49: =C49*(1+'Sensitivity Analysis(Bull)'!D11) -> -4068.97 | E49: =D49*(1+'Sensitivity Analysis(Bull)'!E11) -> -4435.1773 | F49: =E49*(1+'Sensitivity Analysis(Bull)'!F11) -> -4745.6397 | G49: =F49*(1+'Sensitivity Analysis(Bull)'!G11) -> -4982.9217 | H49: =G49*(1+'Sensitivity Analysis(Bull)'!H11) -> -5182.2386 | I49: =H49*(1+'Sensitivity Analysis(Bull)'!I11) -> -5337.7057 | J49: =I49*(1+'Sensitivity Analysis(Bull)'!J11) -> -5497.8369 | K49: =J49*(1+'Sensitivity Analysis(Bull)'!K11) -> -5662.772 | ... M49: =L49*(1+'Sensitivity Analysis(Bull)'!M11) -> -6007.6348
B50: SUBTRACT NEW NET WORKING CAPITAL | D50: =(D32-C32)*'Sensitivity Analysis(Bull)'!D12 -> 1750.86 | E50: =(E32-D32)*'Sensitivity Analysis(Bull)'!E12 -> 4167.0468 | F50: =(F32-E32)*'Sensitivity Analysis(Bull)'!F12 -> 6350.2525 | G50: =(G32-F32)*'Sensitivity Analysis(Bull)'!G12 -> 8121.2065 | H50: =(H32-G32)*'Sensitivity Analysis(Bull)'!H12 -> 9598.2068 | I50: =(I32-H32)*'Sensitivity Analysis(Bull)'!I12 -> 9248.1546 | J50: =(J32-I32)*'Sensitivity Analysis(Bull)'!J12 -> 8283.7042 | K50: =(K32-J32)*'Sensitivity Analysis(Bull)'!K12 -> 7523.1095 | ... M50: =(M32-L32)*'Sensitivity Analysis(Bull)'!M12 -> 2897.4002
B51: FREE CASH FLOW | C51: =SUM(C46:C50) -> -627490 | D51: =SUM(D46:D50) -> -6403.11 | E51: =SUM(E46:E50) -> 18891.65 | F51: =SUM(F46:F50) -> 51038.549 | G51: =SUM(G46:G50) -> 90000.286 | H51: =SUM(H46:H50) -> 131451.33 | I51: =SUM(I46:I50) -> 171901.46 | J51: =SUM(J46:J50) -> 214976.68 | ... L51: =SUM(L46:L50) -> 229271.38 | M51: =ROUND((SUM(M46:M50)),0) -> 237854
...

Sheet Sensitivity Analysis(Bear)
B1: DCF MODEL WITH COMPANY VALUATION
B2: COMPANY NAME | C2: START YEAR | D2: YEARS ENDING | E2: STOCK TICKER SYMBOL | F2: CURRENT PRICE
B3: {=_FV(E3,"Name")} -> EVOLV TECHNOLOGIES HOLDINGS, INC. | C3: 2026 | D3: DEC 31st | E3: #VALUE! | F3: {=_FV(E3,"Price")} -> 6.24
B4: Complete non-shaded cells only.
B5: FORECASTING VARIABLES
B6: YEAR | D6: =C3 -> 2026 | E6: =D6+1 -> 2027 | F6: =E6+1 -> 2028 | G6: =F6+1 -> 2029 | H6: =G6+1 -> 2030 | I6: =H6+1 -> 2031 | J6: =I6+1 -> 2032 | K6: =J6+1 -> 2033 | L6: =K6+1 -> 2034 | M6: =L6+1 -> 2035
B7: REVENUE GROWTH FACTOR | D7: 0.3 | E7: 0.26 | F7: 0.21 | G7: 0.17 | H7: 0.13 | I7: 0.1 | J7: 0.09 | K7: 0.07 | L7: 0.04 | M7: 0.03
B8: EXPECTED GROSS PROFIT MARGIN | D8: 0.51 | E8: 0.53 | F8: 0.54 | G8: 0.55 | H8: 0.56 | I8: 0.57 | J8: 0.58 | K8: 0.58 | L8: 0.58 | M8: 0.58
B9: S, G, & A EXPENSE % OF REVENUE | D9: 0.63 | E9: 0.56 | F9: 0.5 | G9: 0.45 | H9: 0.41 | I9: 0.38 | J9: 0.35 | K9: 0.33 | L9: 0.31 | M9: 0.3
B10: DEPRECIATION & AMORTIZATION % OF REVENUE | D10: 0.17 | E10: 0.15 | F10: 0.14 | G10: 0.13 | H10: 0.12 | I10: 0.11 | J10: 0.11 | K10: 0.1 | L10: 0.1 | M10: 0.09
B11: CAPITAL EXPENDITURE GROWTH FACTOR | D11: 0.12 | E11: 0.12 | F11: 0.1 | G11: 0.07 | H11: 0.06 | I11: 0.05 | J11: 0.04 | K11: 0.04 | L11: 0.04 | M11: 0.04
B12: NET WORKING CAPITAL TO SALES RATIO | D12: 0.07 | E12: 0.1 | F12: 0.12 | G12: 0.14 | H12: 0.17 | I12: 0.17 | J12: 0.17 | K12: 0.17 | L12: 0.17 | M12: 0.17
B14: INCOME TAX RATE | C14: 0.21
B15: ASSUMED LONG-TERM SUSTAINABLE GROWTH RATE | C15: 0.02 | D15: PER YEAR AFTER | E15: =M6 -> 2035
B16: DISCOUNT RATE | C16: =WACC!F9 -> 0.14070057
B18: VALUATION MODEL OUTPUTS
B19: YEAR | D19: =D6 -> 2026 | E19: =E6 -> 2027 | F19: =F6 -> 2028 | G19: =G6 -> 2029 | H19: =H6 -> 2030 | I19: =I6 -> 2031 | J19: =J6 -> 2032 | K19: =K6 -> 2033 | ... M19: =M6 -> 2035
B20: GROSS PROFIT MARGIN | D20: =IFERROR('Sensitivity Analysis(Bear)'!D35/'Sensitivity Analysis(Bear)'!D32,"") -> 0.51000256 | E20: =IFERROR('Sensitivity Analysis(Bear)'!E35/'Sensitivity Analysis(Bear)'!E32,"") -> 0.53000177 | F20: =IFERROR('Sensitivity Analysis(Bear)'!F35/'Sensitivity Analysis(Bear)'!F32,"") -> 0.54000057 | G20: =IFERROR('Sensitivity Analysis(Bear)'!G35/'Sensitivity Analysis(Bear)'!G32,"") -> 0.54999907 | H20: =IFERROR('Sensitivity Analysis(Bear)'!H35/'Sensitivity Analysis(Bear)'!H32,"") -> 0.56000106 | I20: =IFERROR('Sensitivity Analysis(Bear)'!I35/'Sensitivity Analysis(Bear)'!I32,"") -> 0.57000039 | J20: =IFERROR('Sensitivity Analysis(Bear)'!J35/'Sensitivity Analysis(Bear)'!J32,"") -> 0.57999932 | K20: =IFERROR('Sensitivity Analysis(Bear)'!K35/'Sensitivity Analysis(Bear)'!K32,"") -> 0.57999981 | ... M20: =IFERROR('Sensitivity Analysis(Bear)'!M35/'Sensitivity Analysis(Bear)'!M32,"") -> 0.57999951
B21: NET OPERATING PROFIT MARGIN | D21: =IFERROR('Sensitivity Analysis(Bear)'!D46/'Sensitivity Analysis(Bear)'!D32,"") -> -0.28999639 | E21: =IFERROR('Sensitivity Analysis(Bear)'!E46/'Sensitivity Analysis(Bear)'!E32,"") -> -0.17999992 | F21: =IFERROR('Sensitivity Analysis(Bear)'!F46/'Sensitivity Analysis(Bear)'!F32,"") -> -0.099996988 | G21: =IFERROR('Sensitivity Analysis(Bear)'!G46/'Sensitivity Analysis(Bear)'!G32,"") -> -0.030000673 | H21: =IFERROR('Sensitivity Analysis(Bear)'!H46/'Sensitivity Analysis(Bear)'!H32,"") -> 0.030000385 | I21: =IFERROR('Sensitivity Analysis(Bear)'!I46/'Sensitivity Analysis(Bear)'!I32,"") -> 0.080001988 | J21: =IFERROR('Sensitivity Analysis(Bear)'!J46/'Sensitivity Analysis(Bear)'!J32,"") -> 0.11999941 | K21: =IFERROR('Sensitivity Analysis(Bear)'!K46/'Sensitivity Analysis(Bear)'!K32,"") -> 0.14999957 | ... M21: =IFERROR('Sensitivity Analysis(Bear)'!M46/'Sensitivity Analysis(Bear)'!M32,"") -> 0.18999973
B22: FREE CASH FLOW ($ MIL) | D22: ='Sensitivity Analysis(Bear)'!D51/1000000 -> -0.023877455 | E22: ='Sensitivity Analysis(Bear)'!E51/1000000 -> -0.0069206962 | F22: ='Sensitivity Analysis(Bear)'!F51/1000000 -> 0.012439457 | G22: ='Sensitivity Analysis(Bear)'!G51/1000000 -> 0.035204521 | H22: ='Sensitivity Analysis(Bear)'!H51/1000000 -> 0.058984073 | I22: ='Sensitivity Analysis(Bear)'!I51/1000000 -> 0.080271749 | J22: ='Sensitivity Analysis(Bear)'!J51/1000000 -> 0.10548865 | K22: ='Sensitivity Analysis(Bear)'!K51/1000000 -> 0.12144459 | ... M22: ='Sensitivity Analysis(Bear)'!M51/1000000 -> 0.142543
B23: TERMINAL VALUE ($ MIL) | M23: ='Sensitivity Analysis(Bear)'!M53/1000000 -> 1.204583
B25: PRESENT VALUE OF COMPANY OPERATIONS ($ MIL) | D25: ='Sensitivity Analysis(Bear)'!C57/1000000 -> 0.556424
B27: MARKET VALUE OF COMPANY ASSETS ($ MIL) | D27: ='Sensitivity Analysis(Bear)'!C63/1000000 -> 0.613346
C29: ACTUAL | D29: FORECAST ––>
C30: =D6-1 -> 2025 | D30: =C30+1 -> 2026 | E30: =D30+1 -> 2027 | F30: =E30+1 -> 2028 | G30: =F30+1 -> 2029 | H30: =G30+1 -> 2030 | I30: =H30+1 -> 2031 | J30: =I30+1 -> 2032 | K30: =J30+1 -> 2033 | ... M30: =L30+1 -> 2035
B32: TOTAL REVENUE | C32: 145905 | D32: =C32*(1+'Sensitivity Analysis(Bear)'!D7) -> 189676.5 | E32: =D32*(1+'Sensitivity Analysis(Bear)'!E7) -> 238992.39 | F32: =E32*(1+'Sensitivity Analysis(Bear)'!F7) -> 289180.79 | G32: =F32*(1+'Sensitivity Analysis(Bear)'!G7) -> 338341.53 | H32: =G32*(1+'Sensitivity Analysis(Bear)'!H7) -> 382325.92 | I32: =H32*(1+'Sensitivity Analysis(Bear)'!I7) -> 420558.52 | J32: =I32*(1+'Sensitivity Analysis(Bear)'!J7) -> 458408.78 | K32: =J32*(1+'Sensitivity Analysis(Bear)'!K7) -> 490497.4 | ... M32: =L32*(1+'Sensitivity Analysis(Bear)'!M7) -> 525420.81
B34: COST OF GOODS SOLD | C34: 70603 | D34: =ROUND((D32*(1-'Sensitivity Analysis(Bear)'!D8)),0) -> 92941 | E34: =ROUND((E32*(1-'Sensitivity Analysis(Bear)'!E8)),0) -> 112326 | F34: =ROUND((F32*(1-'Sensitivity Analysis(Bear)'!F8)),0) -> 133023 | G34: =ROUND((G32*(1-'Sensitivity Analysis(Bear)'!G8)),0) -> 152254 | H34: =ROUND((H32*(1-'Sensitivity Analysis(Bear)'!H8)),0) -> 168223 | I34: =ROUND((I32*(1-'Sensitivity Analysis(Bear)'!I8)),0) -> 180840 | J34: =ROUND((J32*(1-'Sensitivity Analysis(Bear)'!J8)),0) -> 192532 | K34: =ROUND((K32*(1-'Sensitivity Analysis(Bear)'!K8)),0) -> 206009 | ... M34: =ROUND((M32*(1-'Sensitivity Analysis(Bear)'!M8)),0) -> 220677
B35: GROSS PROFIT | C35: 75302 | D35: =D32-D34 -> 96735.5 | E35: =E32-E34 -> 126666.39 | F35: =F32-F34 -> 156157.79 | G35: =G32-G34 -> 186087.53 | H35: =H32-H34 -> 214102.92 | I35: =I32-I34 -> 239718.52 | J35: =J32-J34 -> 265876.78 | K35: =K32-K34 -> 284488.4 | ... M35: =M32-M34 -> 304743.81
B37: SELLING, GENERAL AND ADMINISTRATIVE EXPENSES | C37: =185897+160635+59796-6491 -> 399837 | D37: =ROUND((D32*'Sensitivity Analysis(Bear)'!D9),0) -> 119496 | E37: =ROUND((E32*'Sensitivity Analysis(Bear)'!E9),0) -> 133836 | F37: =ROUND((F32*'Sensitivity Analysis(Bear)'!F9),0) -> 144590 | G37: =ROUND((G32*'Sensitivity Analysis(Bear)'!G9),0) -> 152254 | H37: =ROUND((H32*'Sensitivity Analysis(Bear)'!H9),0) -> 156754 | I37: =ROUND((I32*'Sensitivity Analysis(Bear)'!I9),0) -> 159812 | J37: =ROUND((J32*'Sensitivity Analysis(Bear)'!J9),0) -> 160443 | K37: =ROUND((K32*'Sensitivity Analysis(Bear)'!K9),0) -> 161864 | ... M37: =ROUND((M32*'Sensitivity Analysis(Bear)'!M9),0) -> 157626
B38: EARNINGS BEFORE INTEREST, TAXES, DEPR. & AMORT. (EBITDA) | C38: =C35-C37 -> -324535 | D38: =D35-D37 -> -22760.5 | E38: =E35-E37 -> -7169.61 | F38: =F35-F37 -> 11567.792 | G38: =G35-G37 -> 33833.527 | H38: =H35-H37 -> 57348.925 | I38: =I35-I37 -> 79906.517 | J38: =J35-J37 -> 105433.78 | ... M38: =M35-M37 -> 147117.81
B40: DEPRECIATION AND AMORTIZATION | C40: 24340 | D40: =ROUND((D32*'Sensitivity Analysis(Bear)'!D10),0) -> 32245 | E40: =ROUND((E32*'Sensitivity Analysis(Bear)'!E10),0) -> 35849 | F40: =ROUND((F32*'Sensitivity Analysis(Bear)'!F10),0) -> 40485 | G40: =ROUND((G32*'Sensitivity Analysis(Bear)'!G10),0) -> 43984 | H40: =ROUND((H32*'Sensitivity Analysis(Bear)'!H10),0) -> 45879 | I40: =ROUND((I32*'Sensitivity Analysis(Bear)'!I10),0) -> 46261 | J40: =ROUND((J32*'Sensitivity Analysis(Bear)'!J10),0) -> 50425 | K40: =ROUND((K32*'Sensitivity Analysis(Bear)'!K10),0) -> 49050 | ... M40: =ROUND((M32*'Sensitivity Analysis(Bear)'!M10),0) -> 47288
B41: EARNINGS BEFORE INTEREST AND TAXES (EBIT) | C41: =C38-C40 -> -348875 | D41: =D38-D40 -> -55005.5 | E41: =E38-E40 -> -43018.61 | F41: =F38-F40 -> -28917.208 | G41: =G38-G40 -> -10150.473 | H41: =H38-H40 -> 11469.925 | I41: =I38-I40 -> 33645.517 | J41: =J38-J40 -> 55008.784 | ... M41: =M38-M40 -> 99829.814
B42: AVAILABLE TAX-LOSS CARRYFORWARDS | C42: 0 | D42: =IF(C42+C41<0,C42+C41,0) -> -348875 | E42: =IF(D42+D41<0,D42+D41,0) -> -403880.5 | F42: =IF(E42+E41<0,E42+E41,0) -> -446899.11 | G42: =IF(F42+F41<0,F42+F41,0) -> -475816.32 | H42: =IF(G42+G41<0,G42+G41,0) -> -485966.79 | I42: =IF(H42+H41<0,H42+H41,0) -> -474496.87 | J42: =IF(I42+I41<0,I42+I41,0) -> -440851.35 | K42: =IF(J42+J41<0,J42+J41,0) -> -385842.57 | ... M42: =IF(L42+L41<0,L42+L41,0) -> -225547.87
B43: NET TAXABLE EARNINGS | C43: =IF(SUM(C41:C42)<0,0,SUM(C41:C42)) -> 0 | D43: =IF(SUM(D41:D42)<0,0,SUM(D41:D42)) -> 0 | E43: =IF(SUM(E41:E42)<0,0,SUM(E41:E42)) -> 0 | F43: =IF(SUM(F41:F42)<0,0,SUM(F41:F42)) -> 0 | G43: =IF(SUM(G41:G42)<0,0,SUM(G41:G42)) -> 0 | H43: =IF(SUM(H41:H42)<0,0,SUM(H41:H42)) -> 0 | I43: =IF(SUM(I41:I42)<0,0,SUM(I41:I42)) -> 0 | J43: =IF(SUM(J41:J42)<0,0,SUM(J41:J42)) -> 0 | ... M43: =IF(SUM(M41:M42)<0,0,SUM(M41:M42)) -> 0
B45: FEDERAL AND STATE INCOME TAXES | C45: 299222 | D45: =D43*'Sensitivity Analysis(Bear)'!$C$14 -> 0 | E45: =E43*'Sensitivity Analysis(Bear)'!$C$14 -> 0 | F45: =F43*'Sensitivity Analysis(Bear)'!$C$14 -> 0 | G45: =G43*'Sensitivity Analysis(Bear)'!$C$14 -> 0 | H45: =H43*'Sensitivity Analysis(Bear)'!$C$14 -> 0 | I45: =I43*'Sensitivity Analysis(Bear)'!$C$14 -> 0 | J45: =J43*'Sensitivity Analysis(Bear)'!$C$14 -> 0 | K45: =K43*'Sensitivity Analysis(Bear)'!$C$14 -> 0 | ... M45: =M43*'Sensitivity Analysis(Bear)'!$C$14 -> 0
B46: NET OPERATING PROFIT AFTER-TAX (NOPAT) | C46: =C41-C45 -> -648097 | D46: =D41-D45 -> -55005.5 | E46: =E41-E45 -> -43018.61 | F46: =F41-F45 -> -28917.208 | G46: =G41-G45 -> -10150.473 | H46: =H41-H45 -> 11469.925 | I46: =I41-I45 -> 33645.517 | J46: =J41-J45 -> 55008.784 | ... M46: =M41-M45 -> 99829.814
B48: ADD BACK DEPRECIATION AND AMORTIZATION | C48: =C40 -> 24340 | D48: =D40 -> 32245 | E48: =E40 -> 35849 | F48: =F40 -> 40485 | G48: =G40 -> 43984 | H48: =H40 -> 45879 | I48: =I40 -> 46261 | J48: =J40 -> 50425 | ... M48: =M40 -> 47288
B49: SUBTRACT CAPITAL EXPENDITURES | C49: -3733 | D49: =C49*(1+'Sensitivity Analysis(Bear)'!D11) -> -4180.96 | E49: =D49*(1+'Sensitivity Analysis(Bear)'!E11) -> -4682.6752 | F49: =E49*(1+'Sensitivity Analysis(Bear)'!F11) -> -5150.9427 | G49: =F49*(1+'Sensitivity Analysis(Bear)'!G11) -> -5511.5087 | H49: =G49*(1+'Sensitivity Analysis(Bear)'!H11) -> -5842.1992 | I49: =H49*(1+'Sensitivity Analysis(Bear)'!I11) -> -6134.3092 | J49: =I49*(1+'Sensitivity Analysis(Bear)'!J11) -> -6379.6816 | K49: =J49*(1+'Sensitivity Analysis(Bear)'!K11) -> -6634.8688 | ... M49: =L49*(1+'Sensitivity Analysis(Bear)'!M11) -> -7176.2741
B50: SUBTRACT NEW NET WORKING CAPITAL | D50: =(D32-C32)*'Sensitivity Analysis(Bear)'!D12 -> 3064.005 | E50: =(E32-D32)*'Sensitivity Analysis(Bear)'!E12 -> 4931.589 | F50: =(F32-E32)*'Sensitivity Analysis(Bear)'!F12 -> 6022.6082 | G50: =(G32-F32)*'Sensitivity Analysis(Bear)'!G12 -> 6882.5028 | H50: =(H32-G32)*'Sensitivity Analysis(Bear)'!H12 -> 7477.3477 | I50: =(I32-H32)*'Sensitivity Analysis(Bear)'!I12 -> 6499.5407 | J50: =(J32-I32)*'Sensitivity Analysis(Bear)'!J12 -> 6434.5453 | K50: =(K32-J32)*'Sensitivity Analysis(Bear)'!K12 -> 5455.0645 | ... M50: =(M32-L32)*'Sensitivity Analysis(Bear)'!M12 -> 2601.5982
B51: FREE CASH FLOW | C51: =SUM(C46:C50) -> -627490 | D51: =SUM(D46:D50) -> -23877.455 | E51: =SUM(E46:E50) -> -6920.6962 | F51: =SUM(F46:F50) -> 12439.457 | G51: =SUM(G46:G50) -> 35204.521 | H51: =SUM(H46:H50) -> 58984.073 | I51: =SUM(I46:I50) -> 80271.749 | J51: =SUM(J46:J50) -> 105488.65 | ... L51: =SUM(L46:L50) -> 134167.41 | M51: =ROUND((SUM(M46:M50)),0) -> 142543
...
